Workbook

Sheet Backlog
A1: ID | B1: Phase / Tier | C1: Category | D1: Feature | E1: Description | F1: Status | G1: Priority | H1: Effort | I1: Inspired By | J1: Dependencies | K1: Notes
A2: P0.1 | B2: Phase 0 | C2: Infra | D2: Fix docker-compose.yml | E2: Broken volume mount + blank port entry — make Postgres persist cleanly. | F2: Done | G2: Critical | H2: S | I2: Custom
A3: P0.2 | B3: Phase 0 | C3: Infra | D3: Flyway dep + config | E3: Add flyway-core / flyway-database-postgresql, baseline-on-migrate=true. | F3: Done | G3: High | H3: S | I3: Custom | K3: V1__init.sql still TBD
A4: P0.3 | B4: Phase 0 | C4: Infra | D4: ddl-auto → validate | E4: Switch Hibernate to validate once V1 baseline captured. | F4: Deferred | G4: High | H4: S | I4: Custom | J4: P0.2,TEST4 | K4: Blocked on V1 dump
A5: P0.4 | B5: Phase 0 | C5: Testing | D5: Testcontainers + sanity ITs | E5: AbstractIntegrationTest + HealthControllerIT + AccountRepositoryIT. | F5: Done | G5: High | H5: M | I5: Custom
A6: P0.5 | B6: Phase 0 | C6: Infra | D6: GitHub Actions CI | E6: mvn verify + npm build on push / PR. | F6: Done | G6: High | H6: S | I6: Custom | J6: P0.4
A7: P0.6 | B7: Phase 0 | C7: Docs | D7: Sync README with 13 modules | E7: README listed only auth/health/bot — refresh to reality. | F7: Done | G7: Medium | H7: S | I7: Custom
A8: P0.7 | B8: Phase 0 | C8: Infra | D8: Port consolidation 5185/8185/5485 | E8: All app ports end in -185 to avoid collision with other local apps. | F8: Done | G8: Low | H8: S | I8: Custom
A9: P1.1 | B9: Phase 1 | C9: Bot Core | D9: BrowserTravianClient stable login | E9: Tolerant selectors + humanType, retry, captcha-aware fallback. | F9: Done | G9: Critical | H9: L | I9: TravBotSharp
A10: P1.2 | B10: Phase 1 | C10: Bot Core | D10: Village scraping scheduler | E10: VillageScrapeScheduler refreshes resources/buildings on cadence. | F10: Done | G10: Critical | H10: M | I10: TravBotSharp | J10: P1.1
A11: P1.3 | B11: Phase 1 | C11: Bot Core | D11: Build queue executor | E11: BuildQueueScheduler picks next pending item, clicks upgrade. | F11: Done | G11: Critical | H11: L | I11: TravBotSharp | J11: P1.2
A12: P1.4 | B12: Phase 1 | C12: Bot Core | D12: NPC trade automation | E12: Marketplace gid=17 NPC redistribute, gated on Plus/gold. | F12: Done | G12: High | H12: M | I12: TravBotSharp | J12: P1.1
A13: P1.5 | B13: Phase 1 | C13: Bot Core | D13: Farmlist runner | E13: FarmlistSendScheduler + sendFarmlist clicks startFarmListRaid. | F13: Done | G13: Critical | H13: M | I13: TravBotSharp | J13: P1.1
A14: P1.6 | B14: Phase 1 | C14: Bot Core | D14: Hero attribute spend | E14: Auto-allocate unspent points into configured attribute. | F14: Done | G14: High | H14: M | I14: TravBotSharp | J14: P1.1
A15: P1.7 | B15: Phase 1 | C15: Bot Core | D15: Auto re-login on 302 | E15: Wrap NotLoggedInException, trigger login(), retry once. | F15: Done | G15: High | H15: S | I15: TravBotSharp | J15: P1.1 | K15: Auto re-login: SessionRecoveryService, opt-in toggle, 10-min cooldown (2026-07-05)
A16: P1.8 | B16: Phase 1 | C16: Bot Core | D16: Hero adventure auto-runner | E16: Pick safest adventure, send hero, track HP. | F16: Not Started | G16: Medium | H16: M | I16: TravBotSharp | J16: P1.6
A17: P1.9 | B17: Phase 1 | C17: Bot Core | D17: Resource overflow alert | E17: Warehouse > 95% → BotEvent + (later) notification. | F17: Done | G17: Medium | H17: S | I17: Custom | J17: P1.2,NOT1 | K17: ResourceOverflowMonitor >=95%, BotEvent WARN + Discord toggle (2026-07-05)
A18: P1.10 | B18: Phase 1 | C18: Bot Core | D18: Master-builder (gold) protection | E18: Refuse to click gold-only upgrade button when queue full. | F18: Done | G18: High | H18: S | I18: Custom | J18: P1.3
A19: P1.11 | B19: Phase 1 | C19: Bot Core | D19: Server time / Plus / UTC offset scrape | E19: Persist offset + Plus status on every dorf1 scrape. | F19: Done | G19: Medium | H19: S | I19: Custom | J19: P1.2
A20: P1.12 | B20: Phase 1 | C20: Bot Core | D20: Sidebar village auto-discovery | E20: Parse sidebar list to upsert villages without manual config. | F20: Done | G20: Medium | H20: S | I20: Custom | J20: P1.2
A21: P1.13 | B21: Phase 1 | C21: Bot Core | D21: In-game build queue parsing | E21: Read finish-at timestamps from #buildingList sidebar. | F21: Done | G21: Medium | H21: S | I21: Custom | J21: P1.2
A22: P1.14 | B22: Phase 1 | C22: Bot Core | D22: Queue reconciliation RUNNING/DONE | E22: Match scraped page state to local queue rows. | F22: Done | G22: High | H22: S | I22: Custom | J22: P1.13
A23: P2.1 | B23: Phase 2 | C23: Safety | D23: HumanDelay range | E23: Pre-action random delay from configurable min/max. | F23: Done | G23: Critical | H23: S | I23: Custom
A24: P2.2 | B24: Phase 2 | C24: Safety | D24: humanType per-key with stalls | E24: Per-char keypress with 60–180 ms cadence + 6% thinking stalls. | F24: Done | G24: Critical | H24: S | I24: Custom
A25: P2.3 | B25: Phase 2 | C25: Safety | D25: Click-or-navigate human nav | E25: Prefer clicking <a> instead of editing address bar. | F25: Done | G25: Medium | H25: S | I25: Custom
A26: P2.4 | B26: Phase 2 | C26: Safety | D26: Multi-account parallel sessions | E26: Per-account browser via BrowserSessionManager + ConcurrentHashMap. | F26: Done | G26: High | H26: S | I26: TravBotSharp
A27: P2.6 | B27: Phase 2 | C27: Safety | D27: Playwright proxy injection | E27: Apply AccountProxy when launching Chromium; rotate per account. | F27: Done | G27: Critical | H27: M | I27: Custom | J27: P2.4 | K27: AccountProxy entity exists but unused · Active AccountProxy row applied at Chromium launch via Playwright proxy options (2026-07-05)
A28: P2.7 | B28: Phase 2 | C28: Safety | D28: Rate limiter per account | E28: Bucket4j or token bucket: cap req/min per accountId. | F28: Done | G28: High | H28: M | I28: Custom | K28: ActionRateLimiter: per-account token bucket, maxActionsPerMinute setting (default 20), gates every browser action (2026-07-05)
A29: P2.8 | B29: Phase 2 | C29: Safety | D29: Captcha detect + pause + notif | E29: Detect challenge DOM markers, pause scheduler, notify user. | F29: Done | G29: Critical | H29: M | I29: Custom | J29: NOT1 | K29: CaptchaDetector on dorf1/dorf2 + CaptchaGate pause + session release + Discord notify; manual login resumes (2026-07-05)
A30: P2.9 | B30: Phase 2 | C30: Safety | D30: User-agent / viewport rotation | E30: Per-session UA + viewport randomization at launch. | F30: Done | G30: Medium | H30: S | I30: Custom | J30: P2.4 | K30: BrowserFingerprint: matched UA+viewport pool, randomized per session at context creation (2026-07-05)
A31: P2.10 | B31: Phase 2 | C31: Safety | D31: BotLog UI filters | E31: Frontend filter by account/severity/date/search. | F31: Done | G31: Medium | H31: M | I31: Custom | K31: Backend log exists · Bot log filters: outcome/search/date-range, JPA Specifications (2026-07-05)
A32: P2.11 | B32: Phase 2 | C32: Safety | D32: Headless mode toggle per-account | E32: Per-account boolean: run Chromium without UI. | F32: Done | G32: Low | H32: S | I32: Custom | J32: P2.4 | K32: Per-account headless flag on AccountSettings; BrowserSessionManager reads it at launch; toggle in account settings Browser group (2026-07-05)
A33: P2.12 | B33: Phase 2 | C33: Safety | D33: Mouse path randomization | E33: Curve path before click instead of teleporting. | F33: Not Started | G33: Low | H33: M | I33: Custom
A34: A1 | B34: Tier A | C34: AI Analytics | D34: Incoming attack scraper + TS analyzer | E34: Parse rally point, compute attacker speed/troop class. | F34: Done | G34: Critical | H34: L | I34: Travcotools | J34: P1.2
A35: A2 | B35: Tier A | C35: AI Analytics | D35: Return-catch optimizer | E35: Suggest launch-time so we hit attacker home with no defense. | F35: Done | G35: Critical | H35: M | I35: Custom | J35: A1
A36: A3 | B36: Tier A | C36: AI Analytics | D36: Inactive search (map.sql) | E36: Parse daily map.sql dump, flag inactive players with filters. | F36: Done | G36: High | H36: L | I36: Travcotools
A37: B1 | B37: Tier B | C37: Analytics | D37: Farmlist analyzer + traffic-light | E37: Parse berichte.php raid reports, attribute, score per target. | F37: Done | G37: High | H37: L | I37: Travcotools | J37: P1.5
A38: B2 | B38: Tier B | C38: AI Analytics | D38: Enemy intel + hero tracker | E38: Snapshot enemy profile, narrate hero/pop changes. | F38: Done | G38: High | H38: L | I38: Custom | J38: A1,A3
A39: B3 | B39: Tier B | C39: AI Analytics | D39: Cropper finder 15c/9c | E39: Heuristic classification from population + capital flag. | F39: Done | G39: Medium | H39: M | I39: Travmap | J39: A3
A40: C1 | B40: Tier C | C40: Notifications | D40: Discord webhook notifier | E40: Push BotEvents to configured webhook URL. | F40: Done | G40: High | H40: S | I40: Travcotools | K40: Was already implemented: DiscordNotifier + settings page + per-event toggles
...

Sheet Summary
A1: Travian-Ultimate Roadmap Summary
A3: By Status | E3: By Priority
A4: Status | B4: Count | C4: % of Total | E4: Priority | F4: Count | G4: % of Total
A5: Done | B5: =COUNTIF(Backlog!F2:F93,"Done") | C5: =IFERROR(B5/SUM($B$5:$B$8),0) | E5: Critical | F5: =COUNTIF(Backlog!G2:G93,"Critical") | G5: =IFERROR(F5/SUM($F$5:$F$8),0)
A6: In Progress | B6: =COUNTIF(Backlog!F2:F93,"In Progress") | C6: =IFERROR(B6/SUM($B$5:$B$8),0) | E6: High | F6: =COUNTIF(Backlog!G2:G93,"High") | G6: =IFERROR(F6/SUM($F$5:$F$8),0)
A7: Deferred | B7: =COUNTIF(Backlog!F2:F93,"Deferred") | C7: =IFERROR(B7/SUM($B$5:$B$8),0) | E7: Medium | F7: =COUNTIF(Backlog!G2:G93,"Medium") | G7: =IFERROR(F7/SUM($F$5:$F$8),0)
A8: Not Started | B8: =COUNTIF(Backlog!F2:F93,"Not Started") | C8: =IFERROR(B8/SUM($B$5:$B$8),0) | E8: Low | F8: =COUNTIF(Backlog!G2:G93,"Low") | G8: =IFERROR(F8/SUM($F$5:$F$8),0)
A9: Total | B9: =SUM(B5:B8)
A11: By Inspiration | E11: Progress by Phase / Tier
A12: Source | B12: Count | E12: Phase / Tier | F12: Done | G12: Total | H12: % Done
A13: TravBotSharp | B13: =COUNTIF(Backlog!I2:I93,"*TravBotSharp*") | E13: Phase 0 | F13: =COUNTIFS(Backlog!B2:B93,"Phase 0",Backlog!F2:F93,"Done") | G13: =COUNTIF(Backlog!B2:B93,"Phase 0") | H13: =IFERROR(F13/G13,0)
A14: Travcotools | B14: =COUNTIF(Backlog!I2:I93,"*Travcotools*") | E14: Phase 1 | F14: =COUNTIFS(Backlog!B2:B93,"Phase 1",Backlog!F2:F93,"Done") | G14: =COUNTIF(Backlog!B2:B93,"Phase 1") | H14: =IFERROR(F14/G14,0)
A15: Travmap | B15: =COUNTIF(Backlog!I2:I93,"*Travmap*") | E15: Phase 2 | F15: =COUNTIFS(Backlog!B2:B93,"Phase 2",Backlog!F2:F93,"Done") | G15: =COUNTIF(Backlog!B2:B93,"Phase 2") | H15: =IFERROR(F15/G15,0)
A16: Gettertools | B16: =COUNTIF(Backlog!I2:I93,"*Gettertools*") | E16: Tier A | F16: =COUNTIFS(Backlog!B2:B93,"Tier A",Backlog!F2:F93,"Done") | G16: =COUNTIF(Backlog!B2:B93,"Tier A") | H16: =IFERROR(F16/G16,0)
A17: Custom | B17: =COUNTIF(Backlog!I2:I93,"*Custom*") | E17: Tier B | F17: =COUNTIFS(Backlog!B2:B93,"Tier B",Backlog!F2:F93,"Done") | G17: =COUNTIF(Backlog!B2:B93,"Tier B") | H17: =IFERROR(F17/G17,0)
E18: Tier C | F18: =COUNTIFS(Backlog!B2:B93,"Tier C",Backlog!F2:F93,"Done") | G18: =COUNTIF(Backlog!B2:B93,"Tier C") | H18: =IFERROR(F18/G18,0)
E19: Tier D | F19: =COUNTIFS(Backlog!B2:B93,"Tier D",Backlog!F2:F93,"Done") | G19: =COUNTIF(Backlog!B2:B93,"Tier D") | H19: =IFERROR(F19/G19,0)
E20: Tier MAP | F20: =COUNTIFS(Backlog!B2:B93,"Tier MAP",Backlog!F2:F93,"Done") | G20: =COUNTIF(Backlog!B2:B93,"Tier MAP") | H20: =IFERROR(F20/G20,0)
E21: Tier CALC | F21: =COUNTIFS(Backlog!B2:B93,"Tier CALC",Backlog!F2:F93,"Done") | G21: =COUNTIF(Backlog!B2:B93,"Tier CALC") | H21: =IFERROR(F21/G21,0)
E22: Notifications | F22: =COUNTIFS(Backlog!B2:B93,"Notifications",Backlog!F2:F93,"Done") | G22: =COUNTIF(Backlog!B2:B93,"Notifications") | H22: =IFERROR(F22/G22,0)
E23: Security | F23: =COUNTIFS(Backlog!B2:B93,"Security",Backlog!F2:F93,"Done") | G23: =COUNTIF(Backlog!B2:B93,"Security") | H23: =IFERROR(F23/G23,0)
E24: Reliability | F24: =COUNTIFS(Backlog!B2:B93,"Reliability",Backlog!F2:F93,"Done") | G24: =COUNTIF(Backlog!B2:B93,"Reliability") | H24: =IFERROR(F24/G24,0)
E25: Performance | F25: =COUNTIFS(Backlog!B2:B93,"Performance",Backlog!F2:F93,"Done") | G25: =COUNTIF(Backlog!B2:B93,"Performance") | H25: =IFERROR(F25/G25,0)
E26: Testing | F26: =COUNTIFS(Backlog!B2:B93,"Testing",Backlog!F2:F93,"Done") | G26: =COUNTIF(Backlog!B2:B93,"Testing") | H26: =IFERROR(F26/G26,0)
E27: i18n | F27: =COUNTIFS(Backlog!B2:B93,"i18n",Backlog!F2:F93,"Done") | G27: =COUNTIF(Backlog!B2:B93,"i18n") | H27: =IFERROR(F27/G27,0)

Sheet Legend
A1: ROADMAP.xlsx — Column & Value Legend
A3: Status values
A4: Value | B4: Meaning
A5: Done | B5: Implementation complete; in production.
A6: In Progress | B6: Some scaffolding present; not feature-complete.
A7: Deferred | B7: Blocked or intentionally postponed; reason in Notes.
A8: Not Started | B8: Backlog item, not yet picked up.
A10: Priority values
A11: Value | B11: Meaning
A12: Critical | B12: Blocks core flow or security; do first.
A13: High | B13: Materially improves UX / safety / coverage.
A14: Medium | B14: Quality-of-life or strategic edge.
A15: Low | B15: Nice-to-have / polish.
A17: Effort values
A18: Value | B18: Meaning
A19: S | B19: Small (≤ 1 day)
A20: M | B20: Medium (1–3 days)
A21: L | B21: Large (3–7 days)
A22: XL | B22: Extra Large (> 1 week)
A24: Inspired By values
A25: Value | B25: Meaning
A26: TravBotSharp | B26: Local desktop bot — autoplay parity.
A27: Travcotools | B27: Cloud planner — attack/defense/intel parity.
A28: Gettertools | B28: Pure calculators — troop/travel/cost lookup.
A29: Travmap | B29: Interactive world map viewer.
A30: Custom | B30: Original idea not present in inspirations.
A31: Travian | B31: Mirrors a stock feature of the game itself.
A33: Workflow
A34: Value | B34: Meaning
A35: Add new item | B35: Append a row in Backlog; ID convention: <Phase>.<number> or <Tier><number>.
A36: Update status | B36: Change the Status cell; Summary recalculates on save (LibreOffice / Excel).
A37: Mark blocked | B37: Set Status=Deferred and explain in Notes.
A38: Track dependency | B38: List the blocking IDs comma-separated in Dependencies.
